<?xml version="1.0" ?>
<!-- =================================================================================== -->
<!-- |    This document was autogenerated by xacro from /home/fahad/wheel_changing_autonomous_ws/src/wheel_changing_auto_description/urdf/ur10e_wheel_changer.urdf.xacro | -->
<!-- |    EDITING THIS FILE BY HAND IS NOT RECOMMENDED                                 | -->
<!-- =================================================================================== -->
<robot name="ur10e_wheel_changer">
  <!--
    Base UR robot series xacro macro.

    NOTE this is NOT a URDF. It cannot directly be loaded by consumers
    expecting a flattened '.urdf' file. See the top-level '.xacro' for that
    (but note that .xacro must still be processed by the xacro command).

    This file models the base kinematic chain of a UR robot, which then gets
    parameterised by various configuration files to convert it into a UR3(e),
    UR5(e), UR10(e) or UR16e, etc.

    NOTE the default kinematic parameters (i.e., link lengths, frame locations,
    offsets, etc) do not correspond to any particular robot. They are defaults
    only. There WILL be non-zero offsets between the Forward Kinematics results
    in TF (i.e., robot_state_publisher) and the values reported by the Teach
    Pendant.

    For accurate (and robot-specific) transforms, the 'kinematics_parameters_file'
    parameter MUST point to a .yaml file containing the appropriate values for
    the targeted robot.

    If using the UniversalRobots/Universal_Robots_ROS_Driver, follow the steps
    described in the readme of that repository to extract the kinematic
    calibration from the controller and generate the required .yaml file.

    Main author of the migration to yaml configs Ludovic Delval.

    Contributors to previous versions (in no particular order)

     - Denis Stogl
     - Lovro Ivanov
     - Felix Messmer
     - Kelsey Hawkins
     - Wim Meeussen
     - Shaun Edwards
     - Nadia Hammoudeh Garcia
     - Dave Hershberger
     - G. vd. Hoorn
     - Philip Long
     - Dave Coleman
     - Miguel Prada
     - Mathias Luedtke
     - Marcel Schnirring
     - Felix von Drigalski
     - Felix Exner
     - Jimmy Da Silva
     - Ajit Krisshna N L
     - Muhammad Asif Rana
  -->
  <!--
    Custom coaxial dual end-effector for the wheel-changing project.
    - Outer gripper: four larger fingers around wheel rim.
    - Inner socket: small central rotating/socket-like tool for the single center lug nut.
    - Camera: mounted above/behind the coaxial tools at the common neck.

    Version 1 is mainly visual/kinematic. Later we will add real gripper joints,
    contact constraints, and attach/detach plugins.
  -->
  <link name="world"/>
  <!-- Mount/base plate for the UR10e. -->
  <link name="robot_mount">
    <visual>
      <origin rpy="0 0 0" xyz="0 0 -0.03"/>
      <geometry>
        <cylinder length="0.06" radius="0.22"/>
      </geometry>
      <material name="mount_gray">
        <color rgba="0.35 0.35 0.35 1"/>
      </material>
    </visual>
    <collision>
      <origin rpy="0 0 0" xyz="0 0 -0.03"/>
      <geometry>
        <cylinder length="0.06" radius="0.22"/>
      </geometry>
    </collision>
  </link>
  <joint name="world_to_robot_mount" type="fixed">
    <parent link="world"/>
    <child link="robot_mount"/>
    <origin rpy="0 0 0" xyz="0 0 0.04"/>
  </joint>
  <!-- links -  main serial chain -->
  <!-- base_link serves as the root of the robot's kinematic tree. It follows REP-103
        conventions (i.e., X+ forward, Y+ left, Z+ up).
        Since some kinematic solvers forbid having inertia values attached to a root link, we've
        added the base_link_inertia link that carries the visual, collision and inertia
        information.
    -->
  <link name="base_link"/>
  <link name="base_link_inertia">
    <visual>
      <origin rpy="0 0 3.141592653589793" xyz="0 0 0"/>
      <geometry>
        <mesh filename="package://ur_description/meshes/ur10e/visual/base.dae"/>
      </geometry>
    </visual>
    <collision>
      <origin rpy="0 0 3.141592653589793" xyz="0 0 0"/>
      <geometry>
        <mesh filename="package://ur_description/meshes/ur10e/collision/base.stl"/>
      </geometry>
    </collision>
    <inertial>
      <mass value="4.0"/>
      <origin rpy="0 0 0" xyz="0 0 0"/>
      <inertia ixx="0.0061063308908" ixy="0.0" ixz="0.0" iyy="0.0061063308908" iyz="0.0" izz="0.01125"/>
    </inertial>
  </link>
  <link name="shoulder_link">
    <visual>
      <origin rpy="0 0 3.141592653589793" xyz="0 0 0"/>
      <geometry>
        <mesh filename="package://ur_description/meshes/ur10e/visual/shoulder.dae"/>
      </geometry>
    </visual>
    <collision>
      <origin rpy="0 0 3.141592653589793" xyz="0 0 0"/>
      <geometry>
        <mesh filename="package://ur_description/meshes/ur10e/collision/shoulder.stl"/>
      </geometry>
    </collision>
    <inertial>
      <mass value="7.369"/>
      <origin rpy="1.570796326794897 0 0" xyz="0.021 -0.027 0.0"/>
      <inertia ixx="0.03408" ixy="2e-05" ixz="-0.00425" iyy="0.03529" iyz="8e-05" izz="0.02156"/>
    </inertial>
  </link>
  <link name="upper_arm_link">
    <visual>
      <origin rpy="1.5707963267948966 0 -1.5707963267948966" xyz="0 0 0.1762"/>
      <geometry>
        <mesh filename="package://ur_description/meshes/ur10e/visual/upperarm.dae"/>
      </geometry>
    </visual>
    <collision>
      <origin rpy="1.5707963267948966 0 -1.5707963267948966" xyz="0 0 0.1762"/>
      <geometry>
        <mesh filename="package://ur_description/meshes/ur10e/collision/upperarm.stl"/>
      </geometry>
    </collision>
    <inertial>
      <mass value="13.051"/>
      <origin rpy="0 0 0" xyz="-0.2327 0.0 0.158"/>
      <inertia ixx="0.02814" ixy="5e-05" ixz="-0.01561" iyy="0.77068" iyz="2e-05" izz="0.76943"/>
    </inertial>
  </link>
  <link name="forearm_link">
    <visual>
      <origin rpy="1.5707963267948966 0 -1.5707963267948966" xyz="0 0 0.0393"/>
      <geometry>
        <mesh filename="package://ur_description/meshes/ur10e/visual/forearm.dae"/>
      </geometry>
    </visual>
    <collision>
      <origin rpy="1.5707963267948966 0 -1.5707963267948966" xyz="0 0 0.0393"/>
      <geometry>
        <mesh filename="package://ur_description/meshes/ur10e/collision/forearm.stl"/>
      </geometry>
    </collision>
    <inertial>
      <mass value="3.989"/>
      <origin rpy="0 0 0" xyz="-0.33155 0.0 0.068"/>
      <inertia ixx="0.01014" ixy="8e-05" ixz="0.00916" iyy="0.30928" iyz="0.0" izz="0.30646"/>
    </inertial>
  </link>
  <link name="wrist_1_link">
    <visual>
      <origin rpy="1.5707963267948966 0 0" xyz="0 0 -0.135"/>
      <geometry>
        <mesh filename="package://ur_description/meshes/ur10e/visual/wrist1.dae"/>
      </geometry>
    </visual>
    <collision>
      <origin rpy="1.5707963267948966 0 0" xyz="0 0 -0.135"/>
      <geometry>
        <mesh filename="package://ur_description/meshes/ur10e/collision/wrist1.stl"/>
      </geometry>
    </collision>
    <inertial>
      <mass value="2.1"/>
      <origin rpy="1.570796326794897 0 0" xyz="0.0 -0.018 0.007"/>
      <inertia ixx="0.00296" ixy="-1e-05" ixz="0.0" iyy="0.00222" iyz="-0.00024" izz="0.00258"/>
    </inertial>
  </link>
  <link name="wrist_2_link">
    <visual>
      <origin rpy="0 0 0" xyz="0 0 -0.12"/>
      <geometry>
        <mesh filename="package://ur_description/meshes/ur10e/visual/wrist2.dae"/>
      </geometry>
    </visual>
    <collision>
      <origin rpy="0 0 0" xyz="0 0 -0.12"/>
      <geometry>
        <mesh filename="package://ur_description/meshes/ur10e/collision/wrist2.stl"/>
      </geometry>
    </collision>
    <inertial>
      <mass value="1.98"/>
      <origin rpy="-1.570796326794897 0 0" xyz="0.0 0.018 -0.007"/>
      <inertia ixx="0.00296" ixy="-1e-05" ixz="0.0" iyy="0.00222" iyz="-0.00024" izz="0.00258"/>
    </inertial>
  </link>
  <link name="wrist_3_link">
    <visual>
      <origin rpy="1.5707963267948966 0 0" xyz="0 0 -0.1168"/>
      <geometry>
        <mesh filename="package://ur_description/meshes/ur10e/visual/wrist3.dae"/>
      </geometry>
    </visual>
    <collision>
      <origin rpy="1.5707963267948966 0 0" xyz="0 0 -0.1168"/>
      <geometry>
        <mesh filename="package://ur_description/meshes/ur10e/collision/wrist3.stl"/>
      </geometry>
    </collision>
    <inertial>
      <mass value="0.615"/>
      <origin rpy="0 0 0" xyz="0.0 0.0 -0.026"/>
      <inertia ixx="0.0004" ixy="0.0" ixz="0.0" iyy="0.00041" iyz="0.0" izz="0.00034"/>
    </inertial>
  </link>
  <!-- base_joint fixes base_link to the environment -->
  <joint name="base_joint" type="fixed">
    <origin rpy="0 0 0" xyz="0 0 0"/>
    <parent link="robot_mount"/>
    <child link="base_link"/>
  </joint>
  <!-- joints - main serial chain -->
  <joint name="base_link-base_link_inertia" type="fixed">
    <parent link="base_link"/>
    <child link="base_link_inertia"/>
    <!-- 'base_link' is REP-103 aligned (so X+ forward), while the internal
           frames of the robot/controller have X+ pointing backwards.
           Use the joint between 'base_link' and 'base_link_inertia' (a dummy
           link/frame) to introduce the necessary rotation over Z (of pi rad).
      -->
    <origin rpy="0 0 3.141592653589793" xyz="0 0 0"/>
  </joint>
  <joint name="shoulder_pan_joint" type="revolute">
    <parent link="base_link_inertia"/>
    <child link="shoulder_link"/>
    <origin rpy="0 0 0" xyz="0 0 0.1807"/>
    <axis xyz="0 0 1"/>
    <limit effort="330.0" lower="-6.283185307179586" upper="6.283185307179586" velocity="2.0943951023931953"/>
    <dynamics damping="0" friction="0"/>
  </joint>
  <joint name="shoulder_lift_joint" type="revolute">
    <parent link="shoulder_link"/>
    <child link="upper_arm_link"/>
    <origin rpy="1.570796327 0 0" xyz="0 0 0"/>
    <axis xyz="0 0 1"/>
    <limit effort="330.0" lower="-6.283185307179586" upper="6.283185307179586" velocity="2.0943951023931953"/>
    <dynamics damping="0" friction="0"/>
  </joint>
  <joint name="elbow_joint" type="revolute">
    <parent link="upper_arm_link"/>
    <child link="forearm_link"/>
    <origin rpy="0 0 0" xyz="-0.6127 0 0"/>
    <axis xyz="0 0 1"/>
    <limit effort="150.0" lower="-3.141592653589793" upper="3.141592653589793" velocity="3.141592653589793"/>
    <dynamics damping="0" friction="0"/>
  </joint>
  <joint name="wrist_1_joint" type="revolute">
    <parent link="forearm_link"/>
    <child link="wrist_1_link"/>
    <origin rpy="0 0 0" xyz="-0.57155 0 0.17415"/>
    <axis xyz="0 0 1"/>
    <limit effort="54.0" lower="-6.283185307179586" upper="6.283185307179586" velocity="3.141592653589793"/>
    <dynamics damping="0" friction="0"/>
  </joint>
  <joint name="wrist_2_joint" type="revolute">
    <parent link="wrist_1_link"/>
    <child link="wrist_2_link"/>
    <origin rpy="1.570796327 0 0" xyz="0 -0.11985 -2.458164590756244e-11"/>
    <axis xyz="0 0 1"/>
    <limit effort="54.0" lower="-6.283185307179586" upper="6.283185307179586" velocity="3.141592653589793"/>
    <dynamics damping="0" friction="0"/>
  </joint>
  <joint name="wrist_3_joint" type="revolute">
    <parent link="wrist_2_link"/>
    <child link="wrist_3_link"/>
    <origin rpy="1.570796326589793 3.141592653589793 3.141592653589793" xyz="0 0.11655 -2.390480459346185e-11"/>
    <axis xyz="0 0 1"/>
    <limit effort="54.0" lower="-6.283185307179586" upper="6.283185307179586" velocity="3.141592653589793"/>
    <dynamics damping="0" friction="0"/>
  </joint>
  <link name="ft_frame"/>
  <joint name="wrist_3_link-ft_frame" type="fixed">
    <parent link="wrist_3_link"/>
    <child link="ft_frame"/>
    <origin rpy="3.141592653589793 0 0" xyz="0 0 0"/>
  </joint>
  <!-- ROS-Industrial 'base' frame - base_link to UR 'Base' Coordinates transform -->
  <link name="base"/>
  <joint name="base_link-base_fixed_joint" type="fixed">
    <!-- Note the rotation over Z of pi radians - as base_link is REP-103
           aligned (i.e., has X+ forward, Y+ left and Z+ up), this is needed
           to correctly align 'base' with the 'Base' coordinate system of
           the UR controller.
      -->
    <origin rpy="0 0 3.141592653589793" xyz="0 0 0"/>
    <parent link="base_link"/>
    <child link="base"/>
  </joint>
  <!-- ROS-Industrial 'flange' frame - attachment point for EEF models -->
  <link name="flange"/>
  <joint name="wrist_3-flange" type="fixed">
    <parent link="wrist_3_link"/>
    <child link="flange"/>
    <origin rpy="0 -1.5707963267948966 -1.5707963267948966" xyz="0 0 0"/>
  </joint>
  <!-- ROS-Industrial 'tool0' frame - all-zeros tool frame -->
  <link name="tool0"/>
  <joint name="flange-tool0" type="fixed">
    <!-- default toolframe - X+ left, Y+ up, Z+ front -->
    <origin rpy="1.5707963267948966 0 1.5707963267948966" xyz="0 0 0"/>
    <parent link="flange"/>
    <child link="tool0"/>
  </joint>
  <link name="ee_neck_link">
    <inertial>
      <mass value="0.7"/>
      <origin rpy="0 0 0" xyz="0 0 0.04"/>
      <inertia ixx="0.002" ixy="0" ixz="0" iyy="0.002" iyz="0" izz="0.002"/>
    </inertial>
    <visual>
      <origin rpy="0 0 0" xyz="0 0 0.04"/>
      <geometry>
        <cylinder length="0.08" radius="0.055"/>
      </geometry>
      <material name="ee_dark_gray">
        <color rgba="0.12 0.12 0.12 1"/>
      </material>
    </visual>
    <collision>
      <origin rpy="0 0 0" xyz="0 0 0.04"/>
      <geometry>
        <cylinder length="0.08" radius="0.055"/>
      </geometry>
    </collision>
  </link>
  <joint name="ee_mount_joint" type="fixed">
    <parent link="tool0"/>
    <child link="ee_neck_link"/>
    <!-- Tool extends along +Z of tool0 for this first version. If your UR10e tool frame points differently, adjust this rpy. -->
    <origin rpy="0 0 0" xyz="0 0 0.02"/>
  </joint>
  <!-- ========================================================== -->
  <!-- Larger 3-jaw outer wheel gripper                           -->
  <!-- 3 blue hands slide radially outward/inward to grab wheel.  -->
  <!-- ========================================================== -->
  <link name="ee_outer_ring_link">
    <inertial>
      <mass value="0.9"/>
      <origin rpy="0 0 0" xyz="0 0 0.08"/>
      <inertia ixx="0.006" ixy="0" ixz="0" iyy="0.006" iyz="0" izz="0.006"/>
    </inertial>
    <!-- central blue back plate -->
    <visual name="outer_gripper_back_plate">
      <origin rpy="0 0 0" xyz="0 0 0.08"/>
      <geometry>
        <cylinder length="0.018" radius="0.18"/>
      </geometry>
      <material name="ee_blue">
        <color rgba="0.05 0.22 0.75 1.0"/>
      </material>
    </visual>
  </link>
  <joint name="ee_outer_ring_fixed_joint" type="fixed">
    <parent link="ee_neck_link"/>
    <child link="ee_outer_ring_link"/>
    <origin rpy="0 0 0" xyz="0 0 0.04"/>
  </joint>
  <!-- BEGIN_OUTER_HAND_COMMON_SLIDE -->
  <link name="ee_outer_hand_slide_link">
    <inertial>
      <origin rpy="0 0 0" xyz="0 0 0"/>
      <mass value="0.05"/>
      <inertia ixx="1e-5" ixy="0" ixz="0" iyy="1e-5" iyz="0" izz="1e-5"/>
    </inertial>
  </link>
  <joint name="ee_outer_hand_slide_joint" type="prismatic">
    <parent link="ee_outer_ring_link"/>
    <child link="ee_outer_hand_slide_link"/>
    <origin rpy="0 0 0" xyz="0 0 -0.120"/>
    <axis xyz="0 0 1"/>
    <limit effort="300" lower="0.0" upper="0.220" velocity="0.20"/>
    <dynamics damping="1.0" friction="0.1"/>
  </joint>
  <!-- END_OUTER_HAND_COMMON_SLIDE -->
  <!-- Outer wheel hand 1 -->
  <link name="ee_outer_hand1_link">
    <inertial>
      <origin rpy="0 0 0" xyz="0.0125 0 0.1150"/>
      <mass value="0.18"/>
      <inertia ixx="0.0005" ixy="0" ixz="0" iyy="0.0005" iyz="0" izz="0.0005"/>
    </inertial>
    <visual name="outer_hand1_visual">
      <origin rpy="0 0 0" xyz="0.0125 0 0.1150"/>
      <geometry>
        <box size="0.035 0.030 0.280"/>
      </geometry>
      <material name="outer_hand_yellow">
        <color rgba="1.0 0.85 0.05 1.0"/>
      </material>
    </visual>
    <collision name="outer_hand1_collision">
      <origin rpy="0 0 0" xyz="0.0125 0 0.1150"/>
      <geometry>
        <box size="0.035 0.030 0.280"/>
      </geometry>
    </collision>
  </link>
  <joint name="ee_outer_hand1_joint" type="prismatic">
    <parent link="ee_outer_hand_slide_link"/>
    <child link="ee_outer_hand1_link"/>
    <origin rpy="0 0 -2.6180" xyz="-0.1342 -0.0775 0.0750"/>
    <axis xyz="-1 0 0"/>
    <limit effort="300" lower="0.0" upper="0.060" velocity="0.05"/>
    <dynamics damping="3.0" friction="1.0"/>
  </joint>
  <!-- Outer wheel hand 2 -->
  <link name="ee_outer_hand2_link">
    <inertial>
      <origin rpy="0 0 0" xyz="0.0125 0 0.0900"/>
      <mass value="0.18"/>
      <inertia ixx="0.0005" ixy="0" ixz="0" iyy="0.0005" iyz="0" izz="0.0005"/>
    </inertial>
    <visual name="outer_hand2_visual">
      <origin rpy="0 0 0" xyz="0.0125 0 0.0900"/>
      <geometry>
        <box size="0.035 0.030 0.280"/>
      </geometry>
      <material name="outer_hand_yellow">
        <color rgba="1.0 0.85 0.05 1.0"/>
      </material>
    </visual>
    <collision name="outer_hand2_collision">
      <origin rpy="0 0 0" xyz="0.0125 0 0.0900"/>
      <geometry>
        <box size="0.035 0.030 0.280"/>
      </geometry>
    </collision>
  </link>
  <joint name="ee_outer_hand2_joint" type="prismatic">
    <parent link="ee_outer_hand_slide_link"/>
    <child link="ee_outer_hand2_link"/>
    <origin rpy="0 0 1.5708" xyz="0.0000 0.1500 0.0950"/>
    <axis xyz="-1 0 0"/>
    <limit effort="300" lower="0.0" upper="0.060" velocity="0.05"/>
    <dynamics damping="3.0" friction="1.0"/>
  </joint>
  <!-- Outer wheel hand 3 -->
  <link name="ee_outer_hand3_link">
    <inertial>
      <origin rpy="0 0 0" xyz="0.0125 0 0.1150"/>
      <mass value="0.18"/>
      <inertia ixx="0.0005" ixy="0" ixz="0" iyy="0.0005" iyz="0" izz="0.0005"/>
    </inertial>
    <visual name="outer_hand3_visual">
      <origin rpy="0 0 0" xyz="0.0125 0 0.1150"/>
      <geometry>
        <box size="0.035 0.030 0.280"/>
      </geometry>
      <material name="outer_hand_yellow">
        <color rgba="1.0 0.85 0.05 1.0"/>
      </material>
    </visual>
    <collision name="outer_hand3_collision">
      <origin rpy="0 0 0" xyz="0.0125 0 0.1150"/>
      <geometry>
        <box size="0.035 0.030 0.280"/>
      </geometry>
    </collision>
  </link>
  <joint name="ee_outer_hand3_joint" type="prismatic">
    <parent link="ee_outer_hand_slide_link"/>
    <child link="ee_outer_hand3_link"/>
    <origin rpy="0 0 -0.5236" xyz="0.1342 -0.0775 0.0750"/>
    <axis xyz="-1 0 0"/>
    <limit effort="300" lower="0.0" upper="0.060" velocity="0.05"/>
    <dynamics damping="3.0" friction="1.0"/>
  </joint>
  <!-- ========================================================== -->
  <!-- Sliding inner socket mechanism                             -->
  <!-- Socket is shorter and starts behind the outer wheel hands. -->
  <!-- It slides forward to reach the lug nut.                    -->
  <!-- ========================================================== -->
  <link name="ee_socket_slide_link">
    <inertial>
      <origin rpy="0 0 0" xyz="0 0 0"/>
      <mass value="0.05"/>
      <inertia ixx="1e-5" ixy="0" ixz="0" iyy="1e-5" iyz="0" izz="1e-5"/>
    </inertial>
  </link>
  <joint name="ee_socket_slide_joint" type="prismatic">
    <parent link="ee_neck_link"/>
    <child link="ee_socket_slide_link"/>
    <origin rpy="0 0 0" xyz="0 0 0.04"/>
    <axis xyz="0 0 1"/>
    <limit effort="80" lower="0.0" upper="0.160" velocity="0.20"/>
    <dynamics damping="0.4" friction="0.05"/>
  </joint>
  <link name="ee_inner_socket_link">
    <inertial>
      <mass value="0.25"/>
      <origin rpy="0 0 0" xyz="0 0 0.075"/>
      <inertia ixx="0.0007" ixy="0" ixz="0" iyy="0.0007" iyz="0" izz="0.0007"/>
    </inertial>
    <!-- shortened orange socket -->
    <visual name="short_inner_socket_visual">
      <origin rpy="0 0 0" xyz="0 0 0.075"/>
      <geometry>
        <cylinder length="0.130" radius="0.035"/>
      </geometry>
      <material name="ee_orange">
        <color rgba="0.95 0.45 0.08 1"/>
      </material>
    </visual>
  </link>
  <joint name="ee_socket_spin_joint" type="continuous">
    <parent link="ee_socket_slide_link"/>
    <child link="ee_inner_socket_link"/>
    <origin rpy="0 0 0" xyz="0 0 0"/>
    <axis xyz="0 0 1"/>
  </joint>
  <!-- ========================================================== -->
  <!-- 3 small sliding fingers around the shortened socket mouth  -->
  <!-- These grip the center lug nut.                             -->
  <!-- ========================================================== -->
  <link name="ee_finger1_link">
    <visual name="finger1_visual">
      <origin rpy="0 0 0" xyz="-0.015 0 0.003"/>
      <geometry>
        <box size="0.030 0.008 0.014"/>
      </geometry>
      <material name="finger_yellow">
        <color rgba="1.0 0.85 0.05 1.0"/>
      </material>
    </visual>
    <collision name="finger1_collision">
      <origin rpy="0 0 0" xyz="-0.015 0 0.003"/>
      <geometry>
        <box size="0.030 0.008 0.014"/>
      </geometry>
    </collision>
    <inertial>
      <origin rpy="0 0 0" xyz="-0.015 0 0"/>
      <mass value="0.02"/>
      <inertia ixx="1e-5" ixy="0" ixz="0" iyy="1e-5" iyz="0" izz="1e-5"/>
    </inertial>
  </link>
  <joint name="ee_finger1_joint" type="prismatic">
    <parent link="ee_inner_socket_link"/>
    <child link="ee_finger1_link"/>
    <origin rpy="0 0 0" xyz="0.038 0.000 0.145"/>
    <axis xyz="1 0 0"/>
    <limit effort="30" lower="0.0" upper="0.020" velocity="0.05"/>
    <dynamics damping="2.0" friction="0.2"/>
  </joint>
  <link name="ee_finger2_link">
    <visual name="finger2_visual">
      <origin rpy="0 0 0" xyz="-0.015 0 0.003"/>
      <geometry>
        <box size="0.030 0.008 0.014"/>
      </geometry>
      <material name="finger_yellow">
        <color rgba="1.0 0.85 0.05 1.0"/>
      </material>
    </visual>
    <collision name="finger2_collision">
      <origin rpy="0 0 0" xyz="-0.015 0 0.003"/>
      <geometry>
        <box size="0.030 0.008 0.014"/>
      </geometry>
    </collision>
    <inertial>
      <origin rpy="0 0 0" xyz="-0.015 0 0"/>
      <mass value="0.02"/>
      <inertia ixx="1e-5" ixy="0" ixz="0" iyy="1e-5" iyz="0" izz="1e-5"/>
    </inertial>
  </link>
  <joint name="ee_finger2_joint" type="prismatic">
    <parent link="ee_inner_socket_link"/>
    <child link="ee_finger2_link"/>
    <origin rpy="0 0 2.0944" xyz="-0.019 0.0329 0.145"/>
    <axis xyz="1 0 0"/>
    <limit effort="30" lower="0.0" upper="0.020" velocity="0.05"/>
    <dynamics damping="2.0" friction="0.2"/>
  </joint>
  <link name="ee_finger3_link">
    <visual name="finger3_visual">
      <origin rpy="0 0 0" xyz="-0.015 0 0.003"/>
      <geometry>
        <box size="0.030 0.008 0.014"/>
      </geometry>
      <material name="finger_yellow">
        <color rgba="1.0 0.85 0.05 1.0"/>
      </material>
    </visual>
    <collision name="finger3_collision">
      <origin rpy="0 0 0" xyz="-0.015 0 0.003"/>
      <geometry>
        <box size="0.030 0.008 0.014"/>
      </geometry>
    </collision>
    <inertial>
      <origin rpy="0 0 0" xyz="-0.015 0 0"/>
      <mass value="0.02"/>
      <inertia ixx="1e-5" ixy="0" ixz="0" iyy="1e-5" iyz="0" izz="1e-5"/>
    </inertial>
  </link>
  <joint name="ee_finger3_joint" type="prismatic">
    <parent link="ee_inner_socket_link"/>
    <child link="ee_finger3_link"/>
    <origin rpy="0 0 -2.0944" xyz="-0.019 -0.0329 0.145"/>
    <axis xyz="1 0 0"/>
    <limit effort="30" lower="0.0" upper="0.020" velocity="0.05"/>
    <dynamics damping="2.0" friction="0.2"/>
  </joint>
  <link name="ee_camera_link">
    <visual name="camera_body_visual">
      <origin rpy="0 0 0" xyz="0 0 0"/>
      <geometry>
        <box size="0.08 0.05 0.04"/>
      </geometry>
      <material name="camera_black">
        <color rgba="0.02 0.02 0.02 1.0"/>
      </material>
    </visual>
    <inertial>
      <origin rpy="0 0 0" xyz="0 0 0"/>
      <mass value="0.05"/>
      <inertia ixx="0.00002" ixy="0.0" ixz="0.0" iyy="0.00002" iyz="0.0" izz="0.00002"/>
    </inertial>
    <!-- BEGIN_CAMERA_SUPPORT_STICK -->
    <!-- Thin black stick from camera bottom center to arm/end-effector surface -->
    <visual name="camera_support_stick_visual">
      <origin rpy="0 0 0" xyz="0 0 -0.118"/>
      <geometry>
        <cylinder length="0.270" radius="0.005"/>
      </geometry>
      <material name="camera_support_black">
        <color rgba="0.02 0.02 0.02 1.0"/>
      </material>
    </visual>
    <!-- END_CAMERA_SUPPORT_STICK -->
  </link>
  <joint name="ee_camera_joint" type="fixed">
    <parent link="ee_neck_link"/>
    <child link="ee_camera_link"/>
    <!-- Camera placed on the neck, looking forward toward the tool center line. -->
    <origin rpy="1.5708 -1.5708 0" xyz="0 -0.3 -0.13"/>
  </joint>
  <link name="ee_camera_optical_frame"/>
  <joint name="ee_camera_optical_joint" type="fixed">
    <parent link="ee_camera_link"/>
    <child link="ee_camera_optical_frame"/>
    <!-- ROS optical frame: x right, y down, z forward -->
    <origin rpy="-1.5708 0 -1.5708" xyz="0 0 0"/>
  </joint>
  <gazebo reference="ee_camera_link">
    <sensor name="ee_rgbd_camera" type="rgbd_camera">
      <topic>/ee_rgbd_camera</topic>
      <update_rate>30</update_rate>
      <camera>
        <horizontal_fov>1.047</horizontal_fov>
        <image>
          <width>640</width>
          <height>480</height>
          <format>R8G8B8</format>
        </image>
        <clip>
          <near>0.05</near>
          <far>10.0</far>
        </clip>
      </camera>
      <always_on>true</always_on>
      <visualize>true</visualize>
    </sensor>
  </gazebo>
  <!-- BEGIN_SOCKET_FINGER_HIGH_FRICTION -->
  <!-- High friction between socket fingers and lug nut -->
  <gazebo reference="ee_finger1_link">
    <mu1>80.0</mu1>
    <mu2>80.0</mu2>
    <kp>1000000.0</kp>
    <kd>100.0</kd>
  </gazebo>
  <gazebo reference="ee_finger2_link">
    <mu1>80.0</mu1>
    <mu2>80.0</mu2>
    <kp>1000000.0</kp>
    <kd>100.0</kd>
  </gazebo>
  <gazebo reference="ee_finger3_link">
    <mu1>80.0</mu1>
    <mu2>80.0</mu2>
    <kp>1000000.0</kp>
    <kd>100.0</kd>
  </gazebo>
  <!-- END_SOCKET_FINGER_HIGH_FRICTION -->
  <!-- GAZEBO_JOINT_POSITION_CONTROLLERS_START -->
  <!-- Version 1 simple Gazebo joint position controllers for UR10e motion testing. -->
  <gazebo>
    <plugin filename="gz-sim-joint-position-controller-system" name="gz::sim::systems::JointPositionController">
      <joint_name>shoulder_pan_joint</joint_name>
      <topic>/ur10e/shoulder_pan_joint/cmd_pos</topic>
      <use_velocity_commands>false</use_velocity_commands>
      <cmd_max>1000.0</cmd_max>
      <initial_position>0.0</initial_position>
      <cmd_min>-1000.0</cmd_min>
      <p_gain>500.0</p_gain>
      <i_gain>0.0</i_gain>
      <d_gain>30.0</d_gain>
    </plugin>
    <plugin filename="gz-sim-joint-position-controller-system" name="gz::sim::systems::JointPositionController">
      <joint_name>shoulder_lift_joint</joint_name>
      <topic>/ur10e/shoulder_lift_joint/cmd_pos</topic>
      <use_velocity_commands>false</use_velocity_commands>
      <cmd_max>1000.0</cmd_max>
      <initial_position>-0.033929200658769254</initial_position>
      <cmd_min>-1000.0</cmd_min>
      <p_gain>1200.0</p_gain>
      <i_gain>0.0</i_gain>
      <d_gain>80.0</d_gain>
    </plugin>
    <plugin filename="gz-sim-joint-position-controller-system" name="gz::sim::systems::JointPositionController">
      <joint_name>elbow_joint</joint_name>
      <topic>/ur10e/elbow_joint/cmd_pos</topic>
      <use_velocity_commands>false</use_velocity_commands>
      <cmd_max>1000.0</cmd_max>
      <initial_position>-2.6320263251775287</initial_position>
      <cmd_min>-1000.0</cmd_min>
      <p_gain>1000.0</p_gain>
      <i_gain>0.0</i_gain>
      <d_gain>70.0</d_gain>
    </plugin>
    <plugin filename="gz-sim-joint-position-controller-system" name="gz::sim::systems::JointPositionController">
      <joint_name>wrist_1_joint</joint_name>
      <topic>/ur10e/wrist_1_joint/cmd_pos</topic>
      <use_velocity_commands>false</use_velocity_commands>
      <cmd_max>1000.0</cmd_max>
      <initial_position>-0.4410796085640074</initial_position>
      <cmd_min>-1000.0</cmd_min>
      <p_gain>500.0</p_gain>
      <i_gain>0.0</i_gain>
      <d_gain>30.0</d_gain>
    </plugin>
    <plugin filename="gz-sim-joint-position-controller-system" name="gz::sim::systems::JointPositionController">
      <joint_name>wrist_2_joint</joint_name>
      <topic>/ur10e/wrist_2_joint/cmd_pos</topic>
      <use_velocity_commands>false</use_velocity_commands>
      <cmd_max>1000.0</cmd_max>
      <initial_position>1.5959290680236151</initial_position>
      <cmd_min>-1000.0</cmd_min>
      <p_gain>500.0</p_gain>
      <i_gain>0.0</i_gain>
      <d_gain>30.0</d_gain>
    </plugin>
    <plugin filename="gz-sim-joint-position-controller-system" name="gz::sim::systems::JointPositionController">
      <joint_name>wrist_3_joint</joint_name>
      <topic>/ur10e/wrist_3_joint/cmd_pos</topic>
      <use_velocity_commands>false</use_velocity_commands>
      <cmd_max>1000.0</cmd_max>
      <initial_position>0.0</initial_position>
      <cmd_min>-1000.0</cmd_min>
      <p_gain>300.0</p_gain>
      <i_gain>0.0</i_gain>
      <d_gain>20.0</d_gain>
    </plugin>
    <!-- Sliding socket controller -->
    <plugin filename="gz-sim-joint-position-controller-system" name="gz::sim::systems::JointPositionController">
      <joint_name>ee_socket_slide_joint</joint_name>
      <topic>/ur10e/ee_socket_slide_joint/cmd_pos</topic>
      <use_velocity_commands>false</use_velocity_commands>
      <cmd_max>1000.0</cmd_max>
      <initial_position>0.0</initial_position>
      <cmd_min>-1000.0</cmd_min>
      <p_gain>500.0</p_gain>
      <i_gain>0.0</i_gain>
      <d_gain>20.0</d_gain>
    </plugin>
    <!-- Common outer wheel-gripper slide controller -->
    <plugin filename="gz-sim-joint-position-controller-system" name="gz::sim::systems::JointPositionController">
      <joint_name>ee_outer_hand_slide_joint</joint_name>
      <topic>/ur10e/ee_outer_hand_slide_joint/cmd_pos</topic>
      <use_velocity_commands>false</use_velocity_commands>
      <cmd_min>-1000.0</cmd_min>
      <cmd_max>1000.0</cmd_max>
      <initial_position>0.0</initial_position>
      <p_gain>500.0</p_gain>
      <i_gain>0.0</i_gain>
      <d_gain>20.0</d_gain>
    </plugin>
    <!-- OUTER_HAND_RADIAL_CLOSE_CONTROLLERS_BEGIN -->
    <plugin filename="gz-sim-joint-position-controller-system" name="gz::sim::systems::JointPositionController">
      <joint_name>ee_outer_hand1_joint</joint_name>
      <topic>/ur10e/ee_outer_hand1_joint/cmd_pos</topic>
      <use_velocity_commands>false</use_velocity_commands>
      <cmd_min>-1000.0</cmd_min>
      <cmd_max>1000.0</cmd_max>
      <initial_position>0.0</initial_position>
      <p_gain>1200.0</p_gain>
      <i_gain>0.0</i_gain>
      <d_gain>60.0</d_gain>
    </plugin>
    <plugin filename="gz-sim-joint-position-controller-system" name="gz::sim::systems::JointPositionController">
      <joint_name>ee_outer_hand2_joint</joint_name>
      <topic>/ur10e/ee_outer_hand2_joint/cmd_pos</topic>
      <use_velocity_commands>false</use_velocity_commands>
      <cmd_min>-1000.0</cmd_min>
      <cmd_max>1000.0</cmd_max>
      <initial_position>0.0</initial_position>
      <p_gain>1200.0</p_gain>
      <i_gain>0.0</i_gain>
      <d_gain>60.0</d_gain>
    </plugin>
    <plugin filename="gz-sim-joint-position-controller-system" name="gz::sim::systems::JointPositionController">
      <joint_name>ee_outer_hand3_joint</joint_name>
      <topic>/ur10e/ee_outer_hand3_joint/cmd_pos</topic>
      <use_velocity_commands>false</use_velocity_commands>
      <cmd_min>-1000.0</cmd_min>
      <cmd_max>1000.0</cmd_max>
      <initial_position>0.0</initial_position>
      <p_gain>1200.0</p_gain>
      <i_gain>0.0</i_gain>
      <d_gain>60.0</d_gain>
    </plugin>
    <!-- OUTER_HAND_RADIAL_CLOSE_CONTROLLERS_END -->
    <plugin filename="gz-sim-joint-position-controller-system" name="gz::sim::systems::JointPositionController">
      <joint_name>ee_socket_spin_joint</joint_name>
      <topic>/ur10e/ee_socket_spin_joint/cmd_pos</topic>
      <use_velocity_commands>false</use_velocity_commands>
      <cmd_min>-1000.0</cmd_min>
      <cmd_max>6.28</cmd_max>
      <initial_position>0.0</initial_position>
    </plugin>
    <!-- Lug nut finger controllers -->
    <plugin filename="gz-sim-joint-position-controller-system" name="gz::sim::systems::JointPositionController">
      <joint_name>ee_finger1_joint</joint_name>
      <topic>/ur10e/ee_finger1_joint/cmd_pos</topic>
      <use_velocity_commands>false</use_velocity_commands>
      <cmd_min>-100.0</cmd_min>
      <cmd_max>100.0</cmd_max>
      <initial_position>0.0</initial_position>
      <p_gain>1800.0</p_gain>
      <i_gain>0.0</i_gain>
      <d_gain>90.0</d_gain>
    </plugin>
    <plugin filename="gz-sim-joint-position-controller-system" name="gz::sim::systems::JointPositionController">
      <joint_name>ee_finger2_joint</joint_name>
      <topic>/ur10e/ee_finger2_joint/cmd_pos</topic>
      <use_velocity_commands>false</use_velocity_commands>
      <cmd_max>100.0</cmd_max>
      <initial_position>0.0</initial_position>
      <p_gain>1800.0</p_gain>
      <i_gain>0.0</i_gain>
      <d_gain>90.0</d_gain>
      <cmd_min>-100.0</cmd_min>
    </plugin>
    <plugin filename="gz-sim-joint-position-controller-system" name="gz::sim::systems::JointPositionController">
      <joint_name>ee_finger3_joint</joint_name>
      <topic>/ur10e/ee_finger3_joint/cmd_pos</topic>
      <use_velocity_commands>false</use_velocity_commands>
      <cmd_max>100.0</cmd_max>
      <initial_position>0.0</initial_position>
      <p_gain>1800.0</p_gain>
      <i_gain>0.0</i_gain>
      <d_gain>90.0</d_gain>
      <cmd_min>-100.0</cmd_min>
    </plugin>
  </gazebo>
  <!-- GAZEBO_JOINT_POSITION_CONTROLLERS_END -->
</robot>
